2021-10-11 22:19:34,584 INFO    MainThread:13670 [wandb_setup.py:_flush():69] setting env: {}
2021-10-11 22:19:34,584 INFO    MainThread:13670 [wandb_setup.py:_flush():69] setting login settings: {}
2021-10-11 22:19:34,584 INFO    MainThread:13670 [wandb_init.py:_log_setup():348] Logging user logs to /home/ljy/Projects/Yolov5/yolov5/wandb/run-20211011_221934-2cx53g9i/logs/debug.log
2021-10-11 22:19:34,584 INFO    MainThread:13670 [wandb_init.py:_log_setup():349] Logging internal logs to /home/ljy/Projects/Yolov5/yolov5/wandb/run-20211011_221934-2cx53g9i/logs/debug-internal.log
2021-10-11 22:19:34,584 INFO    MainThread:13670 [wandb_init.py:init():381] calling init triggers
2021-10-11 22:19:34,584 INFO    MainThread:13670 [wandb_init.py:init():386] wandb.init called with sweep_config: {}
config: {'weights': 'yolov5s.pt', 'cfg': './models/yolov5s.yaml', 'data': 'data/FLIR.yaml', 'hyp': {'lr0': 0.01, 'lrf': 0.2, 'momentum': 0.937, 'weight_decay': 0.0005, 'warmup_epochs': 3.0, 'warmup_momentum': 0.8, 'warmup_bias_lr': 0.1, 'box': 0.05, 'cls': 0.5, 'cls_pw': 1.0, 'obj': 1.0, 'obj_pw': 1.0, 'iou_t': 0.2, 'anchor_t': 4.0, 'fl_gamma': 0.0, 'hsv_h': 0.015, 'hsv_s': 0.7, 'hsv_v': 0.4, 'degrees': 0.0, 'translate': 0.1, 'scale': 0.5, 'shear': 0.0, 'perspective': 0.0, 'flipud': 0.0, 'fliplr': 0.5, 'mosaic': 1.0, 'mixup': 0.0, 'copy_paste': 0.0}, 'epochs': 300, 'batch_size': 16, 'imgsz': 640, 'rect': False, 'resume': False, 'nosave': False, 'noval': False, 'noautoanchor': False, 'evolve': None, 'bucket': '', 'cache': None, 'image_weights': False, 'device': '', 'multi_scale': False, 'single_cls': False, 'adam': False, 'sync_bn': False, 'workers': 8, 'project': 'runs/train', 'entity': None, 'name': 'exp', 'exist_ok': False, 'quad': False, 'linear_lr': False, 'label_smoothing': 0.0, 'upload_dataset': False, 'bbox_interval': -1, 'save_period': -1, 'artifact_alias': 'latest', 'local_rank': -1, 'freeze': 0, 'patience': 100, 'save_dir': 'runs/train/exp5'}
2021-10-11 22:19:34,584 INFO    MainThread:13670 [wandb_init.py:init():430] starting backend
2021-10-11 22:19:34,584 INFO    MainThread:13670 [backend.py:_multiprocessing_setup():70] multiprocessing start_methods=fork,spawn,forkserver, using: spawn
2021-10-11 22:19:34,592 INFO    MainThread:13670 [backend.py:ensure_launched():135] starting backend process...
2021-10-11 22:19:34,595 INFO    MainThread:13670 [backend.py:ensure_launched():139] started backend process with pid: 14248
2021-10-11 22:19:34,596 INFO    MainThread:13670 [wandb_init.py:init():435] backend started and connected
2021-10-11 22:19:34,597 INFO    MainThread:13670 [wandb_init.py:init():494] updated telemetry
2021-10-11 22:19:34,597 INFO    MainThread:13670 [wandb_init.py:init():517] communicating current version
2021-10-11 22:19:35,267 INFO    MainThread:13670 [wandb_init.py:init():522] got version response upgrade_message: "wandb version 0.12.4 is available!  To upgrade, please run:\n $ pip install wandb --upgrade"

2021-10-11 22:19:35,267 INFO    MainThread:13670 [wandb_init.py:init():530] communicating run to backend with 30 second timeout
2021-10-11 22:19:37,026 INFO    MainThread:13670 [wandb_init.py:init():557] starting run threads in backend
2021-10-11 22:19:42,030 INFO    MainThread:13670 [wandb_run.py:_console_start():1605] atexit reg
2021-10-11 22:19:42,030 INFO    MainThread:13670 [wandb_run.py:_redirect():1479] redirect: SettingsConsole.REDIRECT
2021-10-11 22:19:42,030 INFO    MainThread:13670 [wandb_run.py:_redirect():1484] Redirecting console.
2021-10-11 22:19:42,031 INFO    MainThread:13670 [wandb_run.py:_redirect():1540] Redirects installed.
2021-10-11 22:19:42,031 INFO    MainThread:13670 [wandb_init.py:init():582] run started, returning control to user process
2021-10-11 22:19:42,034 INFO    MainThread:13670 [wandb_run.py:_config_callback():847] config_cb None None {'data_dict': {'path': '/home/ljy/Projects/Yolov5/dataset/', 'train': '/home/ljy/Projects/Yolov5/dataset/images/train', 'val': '/home/ljy/Projects/Yolov5/dataset/images/val', 'test': None, 'nc': 4, 'names': ['People', 'Bicycles', 'Cars', 'Dogs']}}
2021-10-12 14:21:09,071 ERROR   MainThread:13670 [retry.py:__call__():126] Retry attempt failed:
Traceback (most recent call last):
  File "/home/ljy/anaconda3/envs/Deeplearning/lib/python3.8/site-packages/urllib3/connection.py", line 169, in _new_conn
    conn = connection.create_connection(
  File "/home/ljy/anaconda3/envs/Deeplearning/lib/python3.8/site-packages/urllib3/util/connection.py", line 73, in create_connection
    for res in socket.getaddrinfo(host, port, family, socket.SOCK_STREAM):
  File "/home/ljy/anaconda3/envs/Deeplearning/lib/python3.8/socket.py", line 918, in getaddrinfo
    for res in _socket.getaddrinfo(host, port, family, type, proto, flags):
socket.gaierror: [Errno -3] Temporary failure in name resolution

During handling of the above exception, another exception occurred:

Traceback (most recent call last):
  File "/home/ljy/anaconda3/envs/Deeplearning/lib/python3.8/site-packages/urllib3/connectionpool.py", line 699, in urlopen
    httplib_response = self._make_request(
  File "/home/ljy/anaconda3/envs/Deeplearning/lib/python3.8/site-packages/urllib3/connectionpool.py", line 382, in _make_request
    self._validate_conn(conn)
  File "/home/ljy/anaconda3/envs/Deeplearning/lib/python3.8/site-packages/urllib3/connectionpool.py", line 1010, in _validate_conn
    conn.connect()
  File "/home/ljy/anaconda3/envs/Deeplearning/lib/python3.8/site-packages/urllib3/connection.py", line 353, in connect
    conn = self._new_conn()
  File "/home/ljy/anaconda3/envs/Deeplearning/lib/python3.8/site-packages/urllib3/connection.py", line 181, in _new_conn
    raise NewConnectionError(
urllib3.exceptions.NewConnectionError: <urllib3.connection.HTTPSConnection object at 0x7f7b5e2e2460>: Failed to establish a new connection: [Errno -3] Temporary failure in name resolution

During handling of the above exception, another exception occurred:

Traceback (most recent call last):
  File "/home/ljy/anaconda3/envs/Deeplearning/lib/python3.8/site-packages/requests/adapters.py", line 439, in send
    resp = conn.urlopen(
  File "/home/ljy/anaconda3/envs/Deeplearning/lib/python3.8/site-packages/urllib3/connectionpool.py", line 755, in urlopen
    retries = retries.increment(
  File "/home/ljy/anaconda3/envs/Deeplearning/lib/python3.8/site-packages/urllib3/util/retry.py", line 574, in increment
    raise MaxRetryError(_pool, url, error or ResponseError(cause))
urllib3.exceptions.MaxRetryError: HTTPSConnectionPool(host='api.wandb.ai', port=443): Max retries exceeded with url: /graphql (Caused by NewConnectionError('<urllib3.connection.HTTPSConnection object at 0x7f7b5e2e2460>: Failed to establish a new connection: [Errno -3] Temporary failure in name resolution'))

During handling of the above exception, another exception occurred:

Traceback (most recent call last):
  File "/home/ljy/anaconda3/envs/Deeplearning/lib/python3.8/site-packages/wandb/sdk/lib/retry.py", line 102, in __call__
    result = self._call_fn(*args, **kwargs)
  File "/home/ljy/anaconda3/envs/Deeplearning/lib/python3.8/site-packages/wandb/apis/public.py", line 179, in execute
    return self._client.execute(*args, **kwargs)
  File "/home/ljy/anaconda3/envs/Deeplearning/lib/python3.8/site-packages/wandb/vendor/gql-0.2.0/gql/client.py", line 52, in execute
    result = self._get_result(document, *args, **kwargs)
  File "/home/ljy/anaconda3/envs/Deeplearning/lib/python3.8/site-packages/wandb/vendor/gql-0.2.0/gql/client.py", line 60, in _get_result
    return self.transport.execute(document, *args, **kwargs)
  File "/home/ljy/anaconda3/envs/Deeplearning/lib/python3.8/site-packages/wandb/vendor/gql-0.2.0/gql/transport/requests.py", line 38, in execute
    request = requests.post(self.url, **post_args)
  File "/home/ljy/anaconda3/envs/Deeplearning/lib/python3.8/site-packages/requests/api.py", line 117, in post
    return request('post', url, data=data, json=json, **kwargs)
  File "/home/ljy/anaconda3/envs/Deeplearning/lib/python3.8/site-packages/requests/api.py", line 61, in request
    return session.request(method=method, url=url, **kwargs)
  File "/home/ljy/anaconda3/envs/Deeplearning/lib/python3.8/site-packages/requests/sessions.py", line 542, in request
    resp = self.send(prep, **send_kwargs)
  File "/home/ljy/anaconda3/envs/Deeplearning/lib/python3.8/site-packages/requests/sessions.py", line 655, in send
    r = adapter.send(request, **kwargs)
  File "/home/ljy/anaconda3/envs/Deeplearning/lib/python3.8/site-packages/requests/adapters.py", line 516, in send
    raise ConnectionError(e, request=request)
requests.exceptions.ConnectionError: HTTPSConnectionPool(host='api.wandb.ai', port=443): Max retries exceeded with url: /graphql (Caused by NewConnectionError('<urllib3.connection.HTTPSConnection object at 0x7f7b5e2e2460>: Failed to establish a new connection: [Errno -3] Temporary failure in name resolution'))
2021-10-12 14:21:19,735 INFO    MainThread:13670 [wandb_run.py:finish():1275] finishing run 2021ai/YOLOv5/2cx53g9i
